# UnknownException

Represents a checked exception which occurs when an unknown error is thrown, such as
from a rejected promise.

To import and use `UnknownException` from the "Cause" module:

ts
import \* as Cause from "effect/Cause"
// Can be accessed like this
Cause.UnknownException
undefined
